Workbook

Sheet 트레이딩
G1: KBondWatcher | H1: Last Quote | I1: Last PnL | J1: Last Action | N1: 매수일 | O1: 바이백 | P1: 잔여일 | Q1: 이자 | R1: 비용 | S1: 보유일
G2: STOPPED | J2: stop flag detected | N2: =TODAY() -> 46245 | O2: 45953 | P2: =O2-N2 -> -292 | Q2: 640000 | R2: =Q2-O5 -> -207030.14 | S2: =R2*P2 -> 60452800
A3: 3-10 스플체크(내재수익률기준) | U3: 통안손익(2177,누적)
A4: 구분 | B4: 전일수익률 | C4: 금일수익률 | D4: 전일비 | E4: 선물매가 | F4: 시가체크 | G4: 시가비 | H4: 시가상태 | I4: 3선종가 | J4: 10선종가 | M4: 회사조달금리(18311) | N4: 조달금액 | O4: 1일 조달비용 | P4: 만기까지 일 캐리 | S4: 세트거래 | U4: 25.4.2(매수일) | V4: 매수결제일 | W4: 수량 | X4: 매수단가 | Y4: 매도결제일 | Z4: 매도단가 | AA4: 보유일수 | AB4: 조달 | AC4: 손익
A5: 3선 | B5: 3.794 | C5: =_xll.IMDP("FUT","A6569000","국채수익률") -> 3.857 | E5: =_xll.IMDP("FUT","A6569000","선물호가_현재가") -> 103.21 | M5: 3.09166 | N5: 10000000000 | O5: =M5/100/365*N5 -> 847030.14 | P5: =(M5/100-O88)/365*P66 -> 0.00017064584 | Q5: =P5*50000000000 -> 8532292.2 | R5: 1 | S5: 9285 | U5: 45400 | V5: =U5+1 -> 45401 | W5: 500 | X5: 10004.75 | Y5: 45429 | Z5: 10033.91 | AA5: =Y5-V5 -> 28 | AB5: =O26*AA5*W5 -> 1.1858422e+08
A6: 10선 | B6: 4.216 | C6: =_xll.IMDP("FUT","A6769000","국채수익률") -> 4.289 | E6: =_xll.IMDP("FUT","A6769000","선물호가_현재가") -> 105.73 | I6: =-I5/3 -> 0 | J6: =-J5/9 -> 0 | R6: 2 | S6: 9277 | U6: 45401 | V6: =U6+3 -> 45404 | W6: 300 | X6: 10005.75 | Y6: 45429 | Z6: 10033.92 | AA6: =Y6-V6 -> 25 | AB6: =O26*AA6*W6 -> 63527260
A7: sp | B7: =(B6-B5)*100 -> 42.2 | C7: =(C6-C5)*100 -> 43.2 | D7: =C7-B7 -> 1 | F7: =(F6-F5)*100 -> 0 | G7: =C7-F7 -> 43.2 | H7: =IF(G7>0,"스팁","플랫") -> 스팁 | J7: =J6-I6 -> 0 | R7: 평균 | S7: =AVERAGE(S5:S6) -> 9281 | W7: =SUM(W5:W6) -> 800 | X7: =SUMPRODUCT(W5:W6,X5:X6)/W7 -> 10005.125 | Z7: =SUMPRODUCT(W5:W6,Z5:Z6)/W7 -> 10033.914 | AB7: =SUM(AB5:AB6) -> 1.8211148e+08 | AC7: =(Z7-X7)*W7*10000-AB7 -> 48198521
A8: 10-30 스플체크(10선내재수익률, 30년지표) | M8: 선물(15:30분) | N8: 선물종가 | O8: 10년(15:30) | P8: 10년종가 | R8: 3 | S8: 9285
A9: 구분 | B9: 전일수익률 | C9: 금일수익률 | D9: 전일비 | E9: 매매가 | F9: 시가체크 | G9: 시가비 | H9: 종가 | I9: 진입가 | J9: 손익 | O9: =D25 -> 4.207 | R9: 단가 | S9: =AVERAGE(S7:S8) -> 9283 | U9: 9495
A10: 10선 | B10: =B6 -> 4.216 | C10: =C6 -> 4.289 | E10: =E6 -> 105.73 | F10: =F6 -> 0 | H10: =C10 -> 4.289 | I10: -10.3 | M10: 변화 | N10: =N9-M9 -> 0 | O10: =O9-N10/0.09/100 -> 4.207 | P10: =(P9-O10)*100 -> -420.7
A11: 26-2 | B11: 4.522 | C11: =_xll.IMDP("BND","KR103501GG39","장내국채-현재수익률") -> 4.629 | E11: =_xll.IMDP("BND","KR103501GG39","장내국채-현재가격") -> 8337 | H11: 2.882 | I11: 손익sp | R11: 46570 | S11: 46178
A12: sp | B12: =(B11-B10)*100 -> 30.6 | C12: =(C11-C10)*100 -> 34 | D12: =C12-B12 -> 3.4 | F12: =(F11-F10)*100 -> 0 | G12: =C12-F12 -> 34 | H12: =(H11-H10)*100 -> -140.7 | I12: =H12-B12 -> -171.3 | J12: =I12*21*9 -> -32375.7 | R12: =TODAY() -> 46245 | S12: =R11-S11 -> 392
B13: 3.49 | C13: =(B13-C10)*100 -> -79.9 | D13: =-(B12-C13) -> -110.5 | F13: =180*1.3 -> 234 | G13: =8476-8456.73 -> 19.27 | H13: =G13*10 -> 192.7 | I13: =H13-1520 -> -1327.3 | M13: sp 계산기 | O13: 25-5 | P13: 25-11 | Q13: 26-06 | U13: 통안손익(2996,누적)
M14: sp감안수익률 | O14: =Q14-0.031 -> 4.261 | P14: =Q14-0.009 -> 4.283 | Q14: =_xll.IMDP("BND","KR103503GG60","장내국채-현재수익률") -> 4.292 | U14: 통안채(매수일) | V14: 매수결제일 | W14: 수량 | X14: 매수단가 | Y14: 매도결제일 | Z14: 매도단가 | AA14: 보유일수 | AB14: 조달 | AC14: 손익 | AD14: 바이백까지
G15: 200 | H15: 0.004 | I15: =G15*H15/4 -> 0.2 | U15: 46037 | V15: 46038 | W15: 100 | X15: 10057.5 | AA15: =Y15-V15 -> -46038 | AB15: =O26*AA15*$W$15 -> -3.8995573e+10 | AC15: =($Z$15-$X$15)*W15*10000-AB15 -> 2.8938073e+10
A16: 10년 차익거래(매일아침 종가세팅) | F16: =E20*1.5 -> 123 | M16: 손익 계산용(장외거래 나오면 입력) | AB16: =$O$26*$AA$15*W16 -> 0 | AC16: =($Z$15-$X$15)*W16*10000-AB16 -> 0
C17: 조달일수 | D17: 3 | F17: =E20*1.5+53 -> 176 | M17: =A25 -> 국고 25-11 | N17: 전일종가(통합) | O17: 현재가격 | P17: 수익률 | Q17: 수량 | R17: 손익 | S17: 전일비 틱환산 | T17: 대차
A18: 구분 | B18: 전일종가(통합) | C18: 현재가격 | D18: 수익률 | E18: 수량 | F18: 손익 | G18: 전일비 틱환산 | H18: 고/저평 | I18: 100 | J18: 88 | M18: 10년현물 | N18: =B25 -> 9318.79 | O18: 9320.9 | Q18: -150 | R18: =(O18-N18)*Q18*10000 -> -3165000 | S18: =R21/10000/Q19 -> 0.48987547 | T18: 2
A19: 국고 25-5 | B19: 8898.88 | C19: =ROUNDDOWN([1]채권단가계산표!N18,0)-0.5 -> 8900.5 | D19: 4.185 | E19: -100 | F19: =(C19-B19)*E19*10000 -> -1620000 | G19: =F22/10000/E20 -> -59.876719 | H19: =_xll.IMDP("FUT","A6769000","저평가")*100 -> 1.4 | I19: 90 | J19: =J18*I19/I18 -> 79.2 | M19: 10Y선물 | N19: =B26 -> 106.34 | O19: 106.34 | Q19: =-Q18*0.88 -> 132 | R19: =(O19-N19)*Q19*1000000 -> 0
A20: 10선 | B20: =B26 -> 106.34 | C20: =_xll.IMDP("FUT","A6769000","선물호가_현재가") -> 105.73 | D20: =C6 -> 4.289 | E20: 82 | F20: =(C20-B20)*E20*1000000 -> -50020000 | I20: 80 | J20: =J19*I20/I19 -> 70.4 | M20: 조달 | O20: =$M$5/100/365*100000000 -> 8470.3014 | Q20: =Q18 -> -150 | R20: =-O20*Q20*$D$17 -> 3811635.6
A21: 조달 | C21: =$M$5/100/365*100000000 -> 8470.3014 | D21: =(D20-D19)*100 -> 10.4 | E21: =E19 -> -100 | F21: =-C21*E21*$D$17 -> 2541090.4 | I21: 70 | J21: =J20*I21/I20 -> 61.6 | M21: 합계 | R21: =SUM(R18:R20) -> 646635.62
A22: 합계 | F22: =SUM(F19:F21) -> -49098910 | I22: 60 | J22: =J21*I22/I21 -> 52.8 | M22: 스팁이거나, 저평이거나, 매수차익 수익나면 매도차익들간다 | R22: 금요일 매도차익하면 역비용 3일치 안준다… | U22: 통안손익(2996,당일) | W22: 조달 | X22: 2
I23: 50 | J23: =J22*I23/I22 -> 44 | M23: =A19 -> 국고 25-5 | N23: 전일종가(통합) | O23: 현재가격 | P23: 수익률 | Q23: 수량 | R23: 손익 | S23: 전일비 틱환산 | T23: 대차 | V23: 전일종가 | W23: 현재가격 | X23: 수량 | Y23: 손익
A24: 구분 | B24: 전일종가(통합) | C24: 현재가격 | D24: 수익률 | E24: 수량 | F24: 손익 | G24: 전일비 틱환산 | I24: 40 | J24: =J23*I24/I23 -> 35.2 | M24: 10년현물 | N24: =B19 -> 8898.88 | O24: 8900.88 | Q24: -100 | R24: =(O24-N24)*Q24*10000 -> -2000000 | S24: =R27/10000/Q25 -> 0.65986635 | T24: 1 | U24: 통안 | V24: 10065.03 | W24: 10066.59 | X24: 100 | Y24: =(W24-V24)*X24*10000 -> 1560000
A25: 국고 25-11 | B25: 9318.79 | C25: =ROUNDDOWN([1]채권단가계산표!L18,0)-0.5 -> 9320.5 | D25: 4.207 | E25: -100 | F25: =(C25-B25)*E25*10000 -> -1710000 | G25: =F28/10000/E26 -> -60.055579 | I25: 30 | J25: =J24*I25/I24 -> 26.4 | M25: 10Y선물 | N25: =B26 -> 106.34 | O25: =O19 -> 106.34 | Q25: =-Q24*0.82 -> 82 | R25: =(O25-N25)*Q25*1000000 -> 0 | U25: 조달 | Y25: =-$O$26*X24*X22 -> -1694060.3
A26: 10선 | B26: 106.34 | C26: =C20 -> 105.73 | D26: =D20 -> 4.289 | E26: 88 | F26: =(C26-B26)*E26*1000000 -> -53680000 | I26: 20 | J26: =J25*I26/I25 -> 17.6 | M26: 조달 | O26: =$M$5/100/365*100000000 -> 8470.3014 | P26: =(P25-P24)*100 -> 0 | Q26: =Q24 -> -100 | R26: =-O26*Q26*$D$17 -> 2541090.4 | Y26: =Y24+Y25 -> -134060.27
A27: 조달 | C27: =$M$5/100/365*100000000 -> 8470.3014 | D27: =(D26-D25)*100 -> 8.2 | E27: =E25 -> -100 | F27: =-C27*E27*$D$17 -> 2541090.4 | I27: 10 | J27: =J26*I27/I26 -> 8.8 | M27: 합계 | R27: =SUM(R24:R26) -> 541090.41 | U27: 통안레벨첵
A28: 합계 | F28: =SUM(F25:F27) -> -52848910 | I28: 300 | J28: =J27*I28/I27 -> 264 | Q28: =2.3*82+3*88 -> 452.6 | U28: 구분 | V28: 통당 | W28: 통안 | X28: 전일스플/평균 | Y28: 가격(해당물) | Z28: 적정가
A29: 둘중에 지표 아닌게 망가져서 고/저평이 발생해도, 전일 민평 수준에서 체크해서 지표가 살아있으면 종가에 평가로 되돌릴 가능성이 높음 / 반대로 지표가 망가지면 지표먼저 사고, 종가 언저리에 남은거 사도 되겠네 | M29: 종목 | N29: 명목금액 | O29: 대차수수료 | P29: 대차비용(분기) | Q29: CD조달비용 | R29: 역비용 | S29: 총비용/BEP틱 | U29: 전일 | X29: =(V29-W29) -> 0 | Z29: =ROUNDDOWN(Y30,0)-ROUNDDOWN(Y29,0) -> #VALUE!
D30: =D25-D19 -> 0.022 | F30: 0.86 | M30: 25-5 | N30: 100 | O30: 0.005 | P30: =N30*O30/365*$P$66 -> 0.046575342 | Q30: =N30*$O$88/365*$P$66 -> 0.27092566 | R30: =N30*$M$5%/365*$P$66 -> 0.28799025 | S30: =P32+Q32-R32 -> 0.041322886 | U30: 금일 | W30: =V30-AVERAGE(X29:X30) -> 0 | Y30: =ROUNDDOWN([1]채권단가계산표!R18,0)-0.5 -> #VALUE! | AB30: =0.85*10103*100 -> 858755
A31: 구분 | B31: 전일종가(통합) | C31: 현재가격 | D31: 수익률 | E31: 수량 | F31: 손익 | G31: 전일비 틱환산 | I31: IRS(10Y) | M31: 24-13 | N31: 100 | O31: 0.0031 | P31: =N31*O31/365*P66 -> 0.028876712 | Q31: =N31*$O$88/365*$P$66 -> 0.27092566 | R31: =N31*$M$5%/365*$P$66 -> 0.28799025 | S31: =S30/0.0168 -> 2.4596956
A32: 국고 26-6 | B32: 10095.5 | C32: =_xll.IMDP("BND","KR103503GG60","장내국채-현재가격") -> 10038 | D32: =_xll.IMDP("BND","KR103503GG60","장내국채-현재수익률") -> 4.292 | E32: -100 | F32: =(C32-B32)*E32*10000 -> 57500000 | G32: =F35/10000/E33 -> 6.4618993 | I32: 2.5525 | P32: =SUM(P30:P31) -> 0.075452055 | Q32: =SUM(Q30:Q31) -> 0.54185132 | R32: =SUM(R30:R31) -> 0.57598049 | U32: =U33/170 -> 25.035294
A33: 10선 | B33: =B26 -> 106.34 | C33: =_xll.IMDP("FUT","A6769000","선물호가_현재가") -> 105.73 | D33: =D26 -> 4.289 | E33: 89 | F33: =(C33-B33)*E33*1000000 -> -54290000 | I33: 본드스왑 | J33: =14*5 -> 70 | M33: =7.8944/2.7725 -> 2.847394 | N33: =P32/P66 -> 0.0022191781 | O33: 틱환산(bep) | P33: =-P32/0.0168 -> -4.4911937 | R33: =R32/P66 -> 0.016940603 | T33: =76*7 -> 532 | U33: =T33*8 -> 4256
A34: 조달 | C34: =$M$5/100/365*100000000 -> 8470.3014 | D34: =(D33-D32)*100 -> -0.3 | E34: =E32 -> -100 | F34: =-C34*E34*$D$17 -> 2541090.4 | I34: =I32-P14 -> -1.7305 | M34: 커브 SP | W34: 비율헤지 손익 계산용
A35: 합계 | F35: =SUM(F32:F34) -> 5751090.4 | M35: 구분 | N35: 전일종가(통합) | O35: 현재가격 | P35: 수익률 | Q35: 수량 | R35: 손익 | S35: 듀레이션 | T35: 델타 | U35: 헤지수량 | W35: 전일종가 | X35: 금일종가 | Y35: 수익률 | Z35: 수량 | AA35: 조달 | AB35: 캐리 | AC35: 대차비용 | AD35: 총비용 | AE35: 손익 | AF35: 듀레이션
D36: =(D32-D25)*100 -> 8.5 | M36: 26-6 | O36: 10080.12 | Q36: 90 | R36: =(O36-N36)*Q36*10000 -> 9072108000 | S36: 8.13 | T36: =S36*O36*100 -> 8195137.6 | U36: =T37/T36 -> 0.90193406 | V36: 26.09.03 | W36: =V24 -> 10065.03 | AA36: =-O26*Z36*$D$17 -> 0 | AE36: =(X36-W36)*Z36*10000 -> 0 | AF36: 1.0426
M37: 25-11 | N37: =B25 -> 9318.79 | O37: =O18 -> 9320.9 | Q37: -100 | R37: =(O37-N37)*Q37*10000 -> -2110000 | S37: 7.93 | T37: =S37*O37*100 -> 7391473.7 | AA37: =-O26*Z37*D$17 -> 0 | AE37: =(X37-W37)*Z37*10000 -> 0 | AF37: 1.9372
G38: 통당 | H38: 270402 | I38: 270702 | J38: 국당 | M38: 조달 | V38: 3선 | W38: =B47 -> 103.39 | Z38: 0 | AE38: =(X38-W38)*Z38*1000000 -> 0
A39: 매수차익거래 | C39: 조달일수 | D39: =D17 -> 3 | G39: =J41-0.129 -> 3.694 | H39: =J41-0.837 -> 2.986 | I39: =J41-0.512 -> 3.311 | J39: =J43+0.185 -> 4.227 | M39: 소계 | P39: =(P36-P37)*100 -> 0 | R39: =R36+R37 -> 9.069998e+09 | S39: 최초 매수 SP | T39: -1.2 | W39: 합계 | AA39: =AA36+AA37 -> 0 | AD39: =AA39+AB39+AC38 -> 0 | AE39: =AE36+AE38+AD39+AE37 -> 0 | AF39: =SUMPRODUCT(Z36:Z37,AF36:AF37)/SUM(Z36:Z37) -> #DIV/0!
A40: 구분 | B40: 전일종가(통합) | C40: 현재가격 | D40: 수익률 | E40: 수량 | F40: 손익 | G40: 고/저평 | H40: 25-10(3-5) | I40: 25-10 | J40: 26-05 | O40: 교체단가 | P40: -1.2 | S40: 종가SP/전일민평SP
...

Sheet 채권단가계산표
D2: 채권 단가계산
B4: 1 | D4: 종목 입력 | E4: 표준코드 | F4: KR103503GG60 | H4: KR103501GFC3 | J4: KR103501GEC6 | L4: KR103502GFC1 | N4: KR103502GF62 | P4: KR103501GF63 | R4: KR103503GG37 | T4: KR103502GE63 | V4: KR103503GG60 | X4: KR103503GF95
B5: 3사평균 | C5: 민평3사 수익률(산출일) | E5: 종목명 | F5: =_xll.IMDP("BND",F$4,"한글종목명") -> 국고04250-3606(26-6) | H5: =_xll.IMDP("BND",H$4,"한글종목명") -> 국고02750-2812(25-10) | J5: =_xll.IMDP("BND",J$4,"한글종목명") -> 국고02875-2712(24-12) | L5: =_xll.IMDP("BND",L$4,"한글종목명") -> 국고03250-3512(25-11) | N5: =_xll.IMDP("BND",N$4,"한글종목명") -> 국고02625-3506(25-5) | P5: =_xll.IMDP("BND",P$4,"한글종목명") -> 국고02250-2806(25-4) | R5: =_xll.IMDP("BND",R$4,"한글종목명") -> 국고03375-3103(26-3) | T5: =_xll.IMDP("BND",T$4,"한글종목명") -> 국고03500-3406(24-5) | V5: =_xll.IMDP("BND",V$4,"한글종목명") -> 국고04250-3606(26-6) | X5: =_xll.IMDP("BND",X$4,"한글종목명") -> 국고02500-3009(25-8)
B6: 4사평균 | C6: 민평4사 수익률(산출일) | D6: 발행 정보 | E6: 발행일 | F6: =_xll.IMDP("BND",F$4,"발행일") -> 20260610 | H6: =_xll.IMDP("BND",H$4,"발행일") -> 20251210 | J6: =_xll.IMDP("BND",J$4,"발행일") -> 20241210 | L6: =_xll.IMDP("BND",L$4,"발행일") -> 20251210 | N6: =_xll.IMDP("BND",N$4,"발행일") -> 20250610 | P6: =_xll.IMDP("BND",P$4,"발행일") -> 20250610 | R6: =_xll.IMDP("BND",R$4,"발행일") -> 20260310 | T6: =_xll.IMDP("BND",T$4,"발행일") -> 20240610 | V6: =_xll.IMDP("BND",V$4,"발행일") -> 20260610 | X6: =_xll.IMDP("BND",X$4,"발행일") -> 20250910
B7: KAP | C7: KBP 수익률(산출일) | E7: 만기일 | F7: =_xll.IMDP("BND",F$4,"만기일") -> 20360610 | H7: =_xll.IMDP("BND",H$4,"만기일") -> 20281210 | J7: =_xll.IMDP("BND",J$4,"만기일") -> 20271210 | L7: =_xll.IMDP("BND",L$4,"만기일") -> 20351210 | N7: =_xll.IMDP("BND",N$4,"만기일") -> 20350610 | P7: =_xll.IMDP("BND",P$4,"만기일") -> 20280610 | R7: =_xll.IMDP("BND",R$4,"만기일") -> 20310310 | T7: =_xll.IMDP("BND",T$4,"만기일") -> 20340610 | V7: =_xll.IMDP("BND",V$4,"만기일") -> 20360610 | X7: =_xll.IMDP("BND",X$4,"만기일") -> 20300910
B8: KIS | C8: KIS 수익률(산출일) | E8: 발행만기 | F8: =ROUNDDOWN((DATE(LEFT(F7,4),MID(F7,5,2),RIGHT(F7,2))-DATE(LEFT(F6,4),MID(F6,5,2),RIGHT(F6,2)))/365,0)&"Y" -> 10Y | H8: =ROUNDDOWN((DATE(LEFT(H7,4),MID(H7,5,2),RIGHT(H7,2))-DATE(LEFT(H6,4),MID(H6,5,2),RIGHT(H6,2)))/365,0)&"Y" -> 3Y | J8: =ROUNDDOWN((DATE(LEFT(J7,4),MID(J7,5,2),RIGHT(J7,2))-DATE(LEFT(J6,4),MID(J6,5,2),RIGHT(J6,2)))/365,0)&"Y" -> 3Y | L8: =ROUNDDOWN((DATE(LEFT(L7,4),MID(L7,5,2),RIGHT(L7,2))-DATE(LEFT(L6,4),MID(L6,5,2),RIGHT(L6,2)))/365,0)&"Y" -> 10Y | N8: =ROUNDDOWN((DATE(LEFT(N7,4),MID(N7,5,2),RIGHT(N7,2))-DATE(LEFT(N6,4),MID(N6,5,2),RIGHT(N6,2)))/365,0)&"Y" -> 10Y | P8: =ROUNDDOWN((DATE(LEFT(P7,4),MID(P7,5,2),RIGHT(P7,2))-DATE(LEFT(P6,4),MID(P6,5,2),RIGHT(P6,2)))/365,0)&"Y" -> 3Y | R8: =ROUNDDOWN((DATE(LEFT(R7,4),MID(R7,5,2),RIGHT(R7,2))-DATE(LEFT(R6,4),MID(R6,5,2),RIGHT(R6,2)))/365,0)&"Y" -> 5Y | T8: =ROUNDDOWN((DATE(LEFT(T7,4),MID(T7,5,2),RIGHT(T7,2))-DATE(LEFT(T6,4),MID(T6,5,2),RIGHT(T6,2)))/365,0)&"Y" -> 10Y | V8: =ROUNDDOWN((DATE(LEFT(V7,4),MID(V7,5,2),RIGHT(V7,2))-DATE(LEFT(V6,4),MID(V6,5,2),RIGHT(V6,2)))/365,0)&"Y" -> 10Y | X8: =ROUNDDOWN((DATE(LEFT(X7,4),MID(X7,5,2),RIGHT(X7,2))-DATE(LEFT(X6,4),MID(X6,5,2),RIGHT(X6,2)))/365,0)&"Y" -> 5Y
B9: NICE | C9: NIC 수익률(산출일) | E9: 잔존일 | F9: =DATE(LEFT(F7,4),MID(F7,5,2),RIGHT(F7,2))-TODAY() -> 3591 | H9: =DATE(LEFT(H7,4),MID(H7,5,2),RIGHT(H7,2))-TODAY() -> 852 | J9: =DATE(LEFT(J7,4),MID(J7,5,2),RIGHT(J7,2))-TODAY() -> 486 | L9: =DATE(LEFT(L7,4),MID(L7,5,2),RIGHT(L7,2))-TODAY() -> 3408 | N9: =DATE(LEFT(N7,4),MID(N7,5,2),RIGHT(N7,2))-TODAY() -> 3225 | P9: =DATE(LEFT(P7,4),MID(P7,5,2),RIGHT(P7,2))-TODAY() -> 669 | R9: =DATE(LEFT(R7,4),MID(R7,5,2),RIGHT(R7,2))-TODAY() -> 1672 | T9: =DATE(LEFT(T7,4),MID(T7,5,2),RIGHT(T7,2))-TODAY() -> 2860 | V9: =DATE(LEFT(V7,4),MID(V7,5,2),RIGHT(V7,2))-TODAY() -> 3591 | X9: =DATE(LEFT(X7,4),MID(X7,5,2),RIGHT(X7,2))-TODAY() -> 1491
B10: FN | C10: FNP 수익률(산출일) | E10: 이자종류 | F10: =_xll.IMDP("BND",F$4,"이자종류") -> 이표채 | H10: =_xll.IMDP("BND",H$4,"이자종류") -> 이표채 | J10: =_xll.IMDP("BND",J$4,"이자종류") -> 이표채 | L10: =_xll.IMDP("BND",L$4,"이자종류") -> 이표채 | N10: =_xll.IMDP("BND",N$4,"이자종류") -> 이표채 | P10: =_xll.IMDP("BND",P$4,"이자종류") -> 이표채 | R10: =_xll.IMDP("BND",R$4,"이자종류") -> 이표채 | T10: =_xll.IMDP("BND",T$4,"이자종류") -> 이표채 | V10: =_xll.IMDP("BND",V$4,"이자종류") -> 이표채 | X10: =_xll.IMDP("BND",X$4,"이자종류") -> 이표채
E11: 표면이율(%) | F11: =_xll.IMDP("BND",F$4,"표면이율") -> 4.25 | H11: =_xll.IMDP("BND",H$4,"표면이율") -> 2.75 | J11: =_xll.IMDP("BND",J$4,"표면이율") -> 2.875 | L11: =_xll.IMDP("BND",L$4,"표면이율") -> 3.25 | N11: =_xll.IMDP("BND",N$4,"표면이율") -> 2.625 | P11: =_xll.IMDP("BND",P$4,"표면이율") -> 2.25 | R11: =_xll.IMDP("BND",R$4,"표면이율") -> 3.375 | T11: =_xll.IMDP("BND",T$4,"표면이율") -> 3.5 | V11: =_xll.IMDP("BND",V$4,"표면이율") -> 4.25 | X11: =_xll.IMDP("BND",X$4,"표면이율") -> 2.5
E12: 차기이자지급일 | F12: =F35 -> 46366 | H12: =H35 -> 46366 | J12: =J35 -> 46366 | L12: =L35 -> 46366 | N12: =N35 -> 46366 | P12: =P35 -> 46366 | R12: =R35 -> 46275 | T12: =T35 -> 46366 | V12: =V35 -> 46366 | X12: =X35 -> 46275
E13: 이자지급기간 | F13: =_xll.IMDP("BND",F$4,"이자지급기간") -> 06M | H13: =_xll.IMDP("BND",H$4,"이자지급기간") -> 06M | J13: =_xll.IMDP("BND",J$4,"이자지급기간") -> 06M | L13: =_xll.IMDP("BND",L$4,"이자지급기간") -> 06M | N13: =_xll.IMDP("BND",N$4,"이자지급기간") -> 06M | P13: =_xll.IMDP("BND",P$4,"이자지급기간") -> 06M | R13: =_xll.IMDP("BND",R$4,"이자지급기간") -> 06M | T13: =_xll.IMDP("BND",T$4,"이자지급기간") -> 06M | V13: =_xll.IMDP("BND",V$4,"이자지급기간") -> 06M | X13: =_xll.IMDP("BND",X$4,"이자지급기간") -> 06M
E14: 시가평가 | F14: =_xll.IMDP("BND",F$4,INDEX($B$5:$C$10,$B$4,2)) -> 4.235 | H14: =_xll.IMDP("BND",H$4,INDEX($B$5:$C$10,$B$4,2)) -> 3.69 | J14: =_xll.IMDP("BND",J$4,INDEX($B$5:$C$10,$B$4,2)) -> 3.5 | L14: =_xll.IMDP("BND",L$4,INDEX($B$5:$C$10,$B$4,2)) -> 4.226 | N14: =_xll.IMDP("BND",N$4,INDEX($B$5:$C$10,$B$4,2)) -> 4.204 | P14: =_xll.IMDP("BND",P$4,INDEX($B$5:$C$10,$B$4,2)) -> 3.606 | R14: =_xll.IMDP("BND",R$4,INDEX($B$5:$C$10,$B$4,2)) -> 3.987 | T14: =_xll.IMDP("BND",T$4,INDEX($B$5:$C$10,$B$4,2)) -> 4.183 | V14: =_xll.IMDP("BND",V$4,INDEX($B$5:$C$10,$B$4,2)) -> 4.235 | X14: =_xll.IMDP("BND",X$4,INDEX($B$5:$C$10,$B$4,2)) -> 3.95 | Z14: 결제일세팅
D15: 결제 정보 | E15: 결제일 | F15: =$Z$15 -> 46246 | H15: =$Z$15 -> 46246 | J15: =$Z$15 -> 46246 | L15: =$Z$15 -> 46246 | N15: =$Z$15 -> 46246 | P15: =$Z$15 -> 46246 | R15: =$Z$15 -> 46246 | T15: =$Z$15 -> 46246 | V15: =$Z$15 -> 46246 | X15: =$Z$15 -> 46246 | Z15: =WORKDAY(TODAY(),1) -> 46246
C16: =INDEX($C$18:$C$26,$C$17,1) -> 세전수익률 | F16: =[1]트레이딩!P36 -> 0 | H16: =[1]트레이딩!D41 -> 3.68 | J16: =[1]트레이딩!D51 -> 3.991 | L16: =[1]트레이딩!D25 -> 4.207 | N16: =[1]트레이딩!D19 -> 4.185 | P16: =[1]트레이딩!D46 -> 3.6 | R16: =[1]트레이딩!D51 -> 3.991 | T16: =[1]트레이딩!D25 -> 4.207 | V16: =[1]트레이딩!D32 -> 4.224 | X16: =[1]트레이딩!D56 -> 3.927
C17: 1 | D17: 계산값 | E17: 세전수익률 | F17: =_xll.IMBC(F$4,$E17,F$15,F$16,$C$16) -> 0 | H17: =_xll.IMBC(H$4,$E17,H$15,H$16,$C$16) -> 3.68 | J17: =_xll.IMBC(J$4,$E17,J$15,J$16,$C$16) -> 3.991 | L17: =_xll.IMBC(L$4,$E17,L$15,L$16,$C$16) -> 4.207 | N17: =_xll.IMBC(N$4,$E17,N$15,N$16,$C$16) -> 4.185 | P17: =_xll.IMBC(P$4,$E17,P$15,P$16,$C$16) -> 3.6 | R17: =_xll.IMBC(R$4,$E17,R$15,R$16,$C$16) -> 3.991 | T17: =_xll.IMBC(T$4,$E17,T$15,T$16,$C$16) -> 4.207 | V17: =_xll.IMBC(V$4,$E17,V$15,V$16,$C$16) -> 4.224 | X17: =_xll.IMBC(X$4,$E17,X$15,X$16,$C$16) -> 3.927
C18: 세전수익률 | E18: 세전단가 | F18: =_xll.IMBC(F$4,$E18,F$15,F$16,$C$16) -> 14250 | H18: =_xll.IMBC(H$4,$E18,H$15,H$16,$C$16) -> 9841.01 | J18: =_xll.IMBC(J$4,$E18,J$15,J$16,$C$16) -> 9905.78 | L18: =_xll.IMBC(L$4,$E18,L$15,L$16,$C$16) -> 9323.02 | N18: =_xll.IMBC(N$4,$E18,N$15,N$16,$C$16) -> 8902.89 | P18: =_xll.IMBC(P$4,$E18,P$15,P$16,$C$16) -> 9801.38 | R18: =_xll.IMBC(R$4,$E18,R$15,R$16,$C$16) -> 9886.2 | T18: =_xll.IMBC(T$4,$E18,T$15,T$16,$C$16) -> 9591.96 | V18: =_xll.IMBC(V$4,$E18,V$15,V$16,$C$16) -> 10092.89 | X18: =_xll.IMBC(X$4,$E18,X$15,X$16,$C$16) -> 9571.88 | AA18: 10510 | AB18: 10510
C19: 세전단가 | E19: 세후단가 | F19: =_xll.IMBC(F$4,$E19,F$15,F$16,$C$16) -> 14239.8 | H19: =_xll.IMBC(H$4,$E19,H$15,H$16,$C$16) -> 9834.4 | J19: =_xll.IMBC(J$4,$E19,J$15,J$16,$C$16) -> 9898.8 | L19: =_xll.IMBC(L$4,$E19,L$15,L$16,$C$16) -> 9315.2 | N19: =_xll.IMBC(N$4,$E19,N$15,N$16,$C$16) -> 8896.5 | P19: =_xll.IMBC(P$4,$E19,P$15,P$16,$C$16) -> 9795.9 | R19: =_xll.IMBC(R$4,$E19,R$15,R$16,$C$16) -> 9866.4 | T19: =_xll.IMBC(T$4,$E19,T$15,T$16,$C$16) -> 9583.5 | V19: =_xll.IMBC(V$4,$E19,V$15,V$16,$C$16) -> 10082.6 | X19: =_xll.IMBC(X$4,$E19,X$15,X$16,$C$16) -> 9557.1 | AA19: 10510 | AB19: 10510
C20: 세후단가 | E20: 경과이자 | F20: =_xll.IMBC(F$4,$E20,F$15,F$16,$C$16) -> 73.1557 | H20: =_xll.IMBC(H$4,$E20,H$15,H$16,$C$16) -> 47.336 | J20: =_xll.IMBC(J$4,$E20,J$15,J$16,$C$16) -> 49.4877 | L20: =_xll.IMBC(L$4,$E20,L$15,L$16,$C$16) -> 55.9426 | N20: =_xll.IMBC(N$4,$E20,N$15,N$16,$C$16) -> 45.1844 | P20: =_xll.IMBC(P$4,$E20,P$15,P$16,$C$16) -> 38.7295 | R20: =_xll.IMBC(R$4,$E20,R$15,R$16,$C$16) -> 142.1535 | T20: =_xll.IMBC(T$4,$E20,T$15,T$16,$C$16) -> 60.2459 | V20: =_xll.IMBC(V$4,$E20,V$15,V$16,$C$16) -> 73.1557 | X20: =_xll.IMBC(X$4,$E20,X$15,X$16,$C$16) -> 105.2989 | AA20: 505 | AB20: 10005
C21: 3사평균 | E21: 경과세금 | F21: =_xll.IMBC(F$4,$E21,F$15,F$16,$C$16) -> 10.2 | H21: =_xll.IMBC(H$4,$E21,H$15,H$16,$C$16) -> 6.6 | J21: =_xll.IMBC(J$4,$E21,J$15,J$16,$C$16) -> 6.9 | L21: =_xll.IMBC(L$4,$E21,L$15,L$16,$C$16) -> 7.8 | N21: =_xll.IMBC(N$4,$E21,N$15,N$16,$C$16) -> 6.3 | P21: =_xll.IMBC(P$4,$E21,P$15,P$16,$C$16) -> 5.4 | R21: =_xll.IMBC(R$4,$E21,R$15,R$16,$C$16) -> 19.8 | T21: =_xll.IMBC(T$4,$E21,T$15,T$16,$C$16) -> 8.4 | V21: =_xll.IMBC(V$4,$E21,V$15,V$16,$C$16) -> 10.2 | X21: =_xll.IMBC(X$4,$E21,X$15,X$16,$C$16) -> 14.7
C22: 4사평균 | E22: Cleanprice | F22: =_xll.IMBC(F$4,$E22,F$15,F$16,$C$16) -> 14176.844 | H22: =_xll.IMBC(H$4,$E22,H$15,H$16,$C$16) -> 9793.6774 | J22: =_xll.IMBC(J$4,$E22,J$15,J$16,$C$16) -> 9856.2964 | L22: =_xll.IMBC(L$4,$E22,L$15,L$16,$C$16) -> 9267.0775 | N22: =_xll.IMBC(N$4,$E22,N$15,N$16,$C$16) -> 8857.7111 | P22: =_xll.IMBC(P$4,$E22,P$15,P$16,$C$16) -> 9762.659 | R22: =_xll.IMBC(R$4,$E22,R$15,R$16,$C$16) -> 9744.0526 | T22: =_xll.IMBC(T$4,$E22,T$15,T$16,$C$16) -> 9531.7237 | V22: =_xll.IMBC(V$4,$E22,V$15,V$16,$C$16) -> 10019.739 | X22: =_xll.IMBC(X$4,$E22,X$15,X$16,$C$16) -> 9466.5832
C23: BP-3사 | E23: 금액Duration | F23: =_xll.IMBC(F$4,$E23,F$15,F$16,$C$16) -> 119859.6 | H23: =_xll.IMBC(H$4,$E23,H$15,H$16,$C$16) -> 21839.169 | J23: =_xll.IMBC(J$4,$E23,J$15,J$16,$C$16) -> 12689.304 | L23: =_xll.IMBC(L$4,$E23,L$15,L$16,$C$16) -> 73195.03 | N23: =_xll.IMBC(N$4,$E23,N$15,N$16,$C$16) -> 68264.69 | P23: =_xll.IMBC(P$4,$E23,P$15,P$16,$C$16) -> 17274.932 | R23: =_xll.IMBC(R$4,$E23,R$15,R$16,$C$16) -> 40857.687 | T23: =_xll.IMBC(T$4,$E23,T$15,T$16,$C$16) -> 64307.377 | V23: =_xll.IMBC(V$4,$E23,V$15,V$16,$C$16) -> 79861.001 | X23: =_xll.IMBC(X$4,$E23,X$15,X$16,$C$16) -> 36186.492
C24: BP-4사 | E24: MacDuration | F24: =_xll.IMBC(F$4,$E24,F$15,F$16,$C$16) -> 8.4112 | H24: =_xll.IMBC(H$4,$E24,H$15,H$16,$C$16) -> 2.3009 | J24: =_xll.IMBC(J$4,$E24,J$15,J$16,$C$16) -> 1.3065 | L24: =_xll.IMBC(L$4,$E24,L$15,L$16,$C$16) -> 8.1813 | N24: =_xll.IMBC(N$4,$E24,N$15,N$16,$C$16) -> 7.9886 | P24: =_xll.IMBC(P$4,$E24,P$15,P$16,$C$16) -> 1.7942 | R24: =_xll.IMBC(R$4,$E24,R$15,R$16,$C$16) -> 4.2977 | T24: =_xll.IMBC(T$4,$E24,T$15,T$16,$C$16) -> 6.9863 | V24: =_xll.IMBC(V$4,$E24,V$15,V$16,$C$16) -> 8.2468 | X24: =_xll.IMBC(X$4,$E24,X$15,X$16,$C$16) -> 3.9289
C25: 원-3사 | E25: ModDuration | F25: =_xll.IMBC(F$4,$E25,F$15,F$16,$C$16) -> 8.4112 | H25: =_xll.IMBC(H$4,$E25,H$15,H$16,$C$16) -> 2.2192 | J25: =_xll.IMBC(J$4,$E25,J$15,J$16,$C$16) -> 1.281 | L25: =_xll.IMBC(L$4,$E25,L$15,L$16,$C$16) -> 7.851 | N25: =_xll.IMBC(N$4,$E25,N$15,N$16,$C$16) -> 7.6677 | P25: =_xll.IMBC(P$4,$E25,P$15,P$16,$C$16) -> 1.7625 | R25: =_xll.IMBC(R$4,$E25,R$15,R$16,$C$16) -> 4.1328 | T25: =_xll.IMBC(T$4,$E25,T$15,T$16,$C$16) -> 6.7043 | V25: =_xll.IMBC(V$4,$E25,V$15,V$16,$C$16) -> 7.9126 | X25: =_xll.IMBC(X$4,$E25,X$15,X$16,$C$16) -> 3.7805
C26: 원-4사 | E26: 금액Convexity | F26: =_xll.IMBC(F$4,$E26,F$15,F$16,$C$16) -> 1170713 | H26: =_xll.IMBC(H$4,$E26,H$15,H$16,$C$16) -> 60116.762 | J26: =_xll.IMBC(J$4,$E26,J$15,J$16,$C$16) -> 22639.66 | L26: =_xll.IMBC(L$4,$E26,L$15,L$16,$C$16) -> 669698.63 | N26: =_xll.IMBC(N$4,$E26,N$15,N$16,$C$16) -> 599595.4 | P26: =_xll.IMBC(P$4,$E26,P$15,P$16,$C$16) -> 39293.732 | R26: =_xll.IMBC(R$4,$E26,R$15,R$16,$C$16) -> 198733.38 | T26: =_xll.IMBC(T$4,$E26,T$15,T$16,$C$16) -> 501665.26 | V26: =_xll.IMBC(V$4,$E26,V$15,V$16,$C$16) -> 755026.9 | X26: =_xll.IMBC(X$4,$E26,X$15,X$16,$C$16) -> 160006.42
E27: Convexity | F27: =_xll.IMBC(F$4,$E27,F$15,F$16,$C$16) -> 82.1553 | H27: =_xll.IMBC(H$4,$E27,H$15,H$16,$C$16) -> 6.1088 | J27: =_xll.IMBC(J$4,$E27,J$15,J$16,$C$16) -> 2.2855 | L27: =_xll.IMBC(L$4,$E27,L$15,L$16,$C$16) -> 71.8328 | N27: =_xll.IMBC(N$4,$E27,N$15,N$16,$C$16) -> 67.3484 | P27: =_xll.IMBC(P$4,$E27,P$15,P$16,$C$16) -> 4.009 | R27: =_xll.IMBC(R$4,$E27,R$15,R$16,$C$16) -> 20.1021 | T27: =_xll.IMBC(T$4,$E27,T$15,T$16,$C$16) -> 52.3006 | V27: =_xll.IMBC(V$4,$E27,V$15,V$16,$C$16) -> 74.8078 | X27: =_xll.IMBC(X$4,$E27,X$15,X$16,$C$16) -> 16.7163
E28: 잔존일수 | F28: =_xll.IMBC(F$4,$E28,F$15,F$16,$C$16) -> 3590 | H28: =_xll.IMBC(H$4,$E28,H$15,H$16,$C$16) -> 851 | J28: =_xll.IMBC(J$4,$E28,J$15,J$16,$C$16) -> 485 | L28: =_xll.IMBC(L$4,$E28,L$15,L$16,$C$16) -> 3407 | N28: =_xll.IMBC(N$4,$E28,N$15,N$16,$C$16) -> 3224 | P28: =_xll.IMBC(P$4,$E28,P$15,P$16,$C$16) -> 668 | R28: =_xll.IMBC(R$4,$E28,R$15,R$16,$C$16) -> 1671 | T28: =_xll.IMBC(T$4,$E28,T$15,T$16,$C$16) -> 2859 | V28: =_xll.IMBC(V$4,$E28,V$15,V$16,$C$16) -> 3590 | X28: =_xll.IMBC(X$4,$E28,X$15,X$16,$C$16) -> 1490
E29: bpv | F29: =_xll.IMBC(F$4,$E29,F$15,F$16,$C$16) -> 11.986 | H29: =_xll.IMBC(H$4,$E29,H$15,H$16,$C$16) -> 2.184 | J29: =_xll.IMBC(J$4,$E29,J$15,J$16,$C$16) -> 1.2689 | L29: =_xll.IMBC(L$4,$E29,L$15,L$16,$C$16) -> 7.3195 | N29: =_xll.IMBC(N$4,$E29,N$15,N$16,$C$16) -> 6.8265 | P29: =_xll.IMBC(P$4,$E29,P$15,P$16,$C$16) -> 1.7275 | R29: =_xll.IMBC(R$4,$E29,R$15,R$16,$C$16) -> 4.0858 | T29: =_xll.IMBC(T$4,$E29,T$15,T$16,$C$16) -> 6.4307 | V29: =_xll.IMBC(V$4,$E29,V$15,V$16,$C$16) -> 7.9861 | X29: =_xll.IMBC(X$4,$E29,X$15,X$16,$C$16) -> 3.6186
D31: 종목 현금흐름
D33: 현금흐름 | F33: =_xll.IMDT("채권현금흐름",$F$4,$F$34:$G$34,100,F$15,F$16,"","sort=A,DtFmt=1,Pos=20,Orient=V,Title="&F$5&"") -> 국고04250-3606(26-6) | H33: =_xll.IMDT("채권현금흐름",$H$4,$H$34:$I$34,100,H$15,H$16,"","sort=A,DtFmt=1,Pos=20,Orient=V,Title="&H$5&"") -> 국고02750-2812(25-10) | J33: =_xll.IMDT("채권현금흐름",J$4,$J$34:$K$34,100,J$15,J$16,"","sort=A,DtFmt=1,Pos=20,Orient=V,Title="&J$5&"") -> 국고02875-2712(24-12) | L33: =_xll.IMDT("채권현금흐름",L$4,$L$34:$M$34,100,L$15,L$16,"","sort=A,DtFmt=1,Pos=20,Orient=V,Title="&L$5&"") -> 국고03250-3512(25-11) | N33: =_xll.IMDT("채권현금흐름",N$4,$N$34:$O$34,100,N$15,N$16,"","sort=A,DtFmt=1,Pos=20,Orient=V,Title="&N$5&"") -> 국고02625-3506(25-5) | P33: =_xll.IMDT("채권현금흐름",P$4,$P$34:$Q$34,100,P$15,P$16,"","sort=A,DtFmt=1,Pos=20,Orient=V,Title="&P$5&"") -> 국고02250-2806(25-4) | R33: =_xll.IMDT("채권현금흐름",R$4,$R$34:$S$34,100,R$15,R$16,"","sort=A,DtFmt=1,Pos=20,Orient=V,Title="&R$5&"") -> 국고03375-3103(26-3) | T33: =_xll.IMDT("채권현금흐름",T$4,$T$34:$U$34,100,T$15,T$16,"","sort=A,DtFmt=1,Pos=20,Orient=V,Title="&T$5&"") -> 국고03500-3406(24-5) | V33: =_xll.IMDT("채권현금흐름",V$4,$T$34:$U$34,100,V$15,V$16,"","sort=A,DtFmt=1,Pos=20,Orient=V,Title="&V$5&"") -> 국고04250-3606(26-6) | X33: =_xll.IMDT("채권현금흐름",X$4,$T$34:$U$34,100,X$15,X$16,"","sort=A,DtFmt=1,Pos=20,Orient=V,Title="&X$5&"") -> 국고02500-3009(25-8)
B34: 이자 | C34: 3 | F34: 일자 | G34: =INDEX($B$34:$B$42,$C$34,1) -> 현금흐름 | H34: 일자 | I34: =INDEX($B$34:$B$42,$C$35,1) -> 현금흐름 | J34: 일자 | K34: =INDEX($B$34:$B$42,$C$36,1) -> 현금흐름 | L34: 일자 | M34: =INDEX($B$34:$B$42,$C$37,1) -> 현금흐름 | N34: 일자 | O34: =INDEX($B$34:$B$42,$C$38,1) -> 현금흐름 | P34: 일자 | Q34: =INDEX($B$34:$B$42,$C$39,1) -> 현금흐름 | R34: 일자 | S34: =INDEX($B$34:$B$42,$C$40,1) -> 현금흐름 | T34: 일자 | U34: =INDEX($B$34:$B$42,$C$41,1) -> 현금흐름 | V34: 일자 | W34: =INDEX($B$34:$B$42,$C$41,1) -> 현금흐름 | X34: 일자 | Y34: =INDEX($B$34:$B$42,$C$41,1) -> 현금흐름
B35: 원금 | C35: 3 | F35: 46366 | G35: 212.5 | H35: 46366 | I35: 137.5 | J35: 46366 | K35: 143.75 | L35: 46366 | M35: 162.5 | N35: 46366 | O35: 131.25 | P35: 46366 | Q35: 112.5 | R35: 46275 | S35: 168.75 | T35: 46366 | U35: 175 | V35: 46366 | W35: 212.5 | X35: 46275 | Y35: 125
B36: 현금흐름 | C36: 3 | F36: 46548 | G36: 212.5 | H36: 46548 | I36: 137.5 | J36: 46548 | K36: 143.75 | L36: 46548 | M36: 162.5 | N36: 46548 | O36: 131.25 | P36: 46548 | Q36: 112.5 | R36: 46456 | S36: 168.75 | T36: 46548 | U36: 175 | V36: 46548 | W36: 212.5 | X36: 46456 | Y36: 125
B37: YTM | C37: 3 | F37: 46731 | G37: 212.5 | H37: 46731 | I37: 137.5 | J37: 46731 | K37: 10143.75 | L37: 46731 | M37: 162.5 | N37: 46731 | O37: 131.25 | P37: 46731 | Q37: 112.5 | R37: 46640 | S37: 168.75 | T37: 46731 | U37: 175 | V37: 46731 | W37: 212.5 | X37: 46640 | Y37: 125
B38: 만기수익률할인계수 | C38: 3 | F38: 46914 | G38: 212.5 | H38: 46914 | I38: 137.5 | L38: 46914 | M38: 162.5 | N38: 46914 | O38: 131.25 | P38: 46914 | Q38: 10112.5 | R38: 46822 | S38: 168.75 | T38: 46914 | U38: 175 | V38: 46914 | W38: 212.5 | X38: 46822 | Y38: 125
B39: 만기수익률현재가치 | C39: 3 | F39: 47097 | G39: 212.5 | H39: 47097 | I39: 10137.5 | L39: 47097 | M39: 162.5 | N39: 47097 | O39: 131.25 | R39: 47006 | S39: 168.75 | T39: 47097 | U39: 175 | V39: 47097 | W39: 212.5 | X39: 47006 | Y39: 125
B40: SPOT수익률 | C40: 3 | F40: 47279 | G40: 212.5 | L40: 47279 | M40: 162.5 | N40: 47279 | O40: 131.25 | R40: 47187 | S40: 168.75 | T40: 47279 | U40: 175 | V40: 47279 | W40: 212.5 | X40: 47187 | Y40: 125
B41: SPOT할인계수 | C41: 3 | F41: 47462 | G41: 212.5 | L41: 47462 | M41: 162.5 | N41: 47462 | O41: 131.25 | R41: 47371 | S41: 168.75 | T41: 47462 | U41: 175 | V41: 47462 | W41: 212.5 | X41: 47371 | Y41: 125
B42: 이론현재가치 | F42: 47644 | G42: 212.5 | L42: 47644 | M42: 162.5 | N42: 47644 | O42: 131.25 | R42: 47552 | S42: 168.75 | T42: 47644 | U42: 175 | V42: 47644 | W42: 212.5 | X42: 47552 | Y42: 125
F43: 47827 | G43: 212.5 | L43: 47827 | M43: 162.5 | N43: 47827 | O43: 131.25 | R43: 47736 | S43: 168.75 | T43: 47827 | U43: 175 | V43: 47827 | W43: 212.5 | X43: 47736 | Y43: 10125
F44: 48009 | G44: 212.5 | L44: 48009 | M44: 162.5 | N44: 48009 | O44: 131.25 | R44: 47917 | S44: 10168.75 | T44: 48009 | U44: 175 | V44: 48009 | W44: 212.5
...
